[2024-05-12T15:36:28.528+0000] {local_task_job_runner.py:120} INFO - ::group::Pre task execution logs
[2024-05-12T15:36:28.573+0000] {taskinstance.py:2076} INFO - Dependencies all met for dep_context=non-requeueable deps ti=<TaskInstance: simple_mlops_dag.load manual__2024-05-12T15:35:55.995449+00:00 [queued]>
[2024-05-12T15:36:28.590+0000] {taskinstance.py:2076} INFO - Dependencies all met for dep_context=requeueable deps ti=<TaskInstance: simple_mlops_dag.load manual__2024-05-12T15:35:55.995449+00:00 [queued]>
[2024-05-12T15:36:28.591+0000] {taskinstance.py:2306} INFO - Starting attempt 1 of 2
[2024-05-12T15:36:28.635+0000] {taskinstance.py:2330} INFO - Executing <Task(PythonOperator): load> on 2024-05-12 15:35:55.995449+00:00
[2024-05-12T15:36:28.643+0000] {standard_task_runner.py:90} INFO - Running: ['airflow', 'tasks', 'run', 'simple_mlops_dag', 'load', 'manual__2024-05-12T15:35:55.995449+00:00', '--job-id', '23', '--raw', '--subdir', 'DAGS_FOLDER/main.py', '--cfg-path', '/tmp/tmpy1rixb3d']
[2024-05-12T15:36:28.646+0000] {standard_task_runner.py:91} INFO - Job 23: Subtask load
[2024-05-12T15:36:28.651+0000] {logging_mixin.py:188} WARNING - /home/airflow/.local/lib/python3.12/site-packages/airflow/task/task_runner/standard_task_runner.py:61 DeprecationWarning: This process (pid=73) is multi-threaded, use of fork() may lead to deadlocks in the child.
[2024-05-12T15:36:28.652+0000] {standard_task_runner.py:63} INFO - Started process 78 to run task
[2024-05-12T15:36:28.757+0000] {task_command.py:426} INFO - Running <TaskInstance: simple_mlops_dag.load manual__2024-05-12T15:35:55.995449+00:00 [running]> on host 740d50cd7040
[2024-05-12T15:36:28.940+0000] {taskinstance.py:2648} INFO - Exporting env vars: AIRFLOW_CTX_DAG_OWNER='airflow' AIRFLOW_CTX_DAG_ID='simple_mlops_dag' AIRFLOW_CTX_TASK_ID='load' AIRFLOW_CTX_EXECUTION_DATE='2024-05-12T15:35:55.995449+00:00' AIRFLOW_CTX_TRY_NUMBER='1' AIRFLOW_CTX_DAG_RUN_ID='manual__2024-05-12T15:35:55.995449+00:00'
[2024-05-12T15:36:28.941+0000] {taskinstance.py:430} INFO - ::endgroup::
[2024-05-12T15:36:28.962+0000] {logging_mixin.py:188} INFO - -----------Storing data------------
[2024-05-12T15:36:28.968+0000] {taskinstance.py:441} INFO - ::group::Post task execution logs
[2024-05-12T15:36:28.969+0000] {taskinstance.py:2905} ERROR - Task failed with exception
Traceback (most recent call last):
  File "/home/airflow/.local/lib/python3.12/site-packages/airflow/models/taskinstance.py", line 465, in _execute_task
    result = _execute_callable(context=context, **execute_callable_kwargs)
             ^^^^^^^^^^^^^^^^^^^^^^^^^^^^^^^^^^^^^^^^^^^^^^^^^^^^^^^^^^^^^
  File "/home/airflow/.local/lib/python3.12/site-packages/airflow/models/taskinstance.py", line 432, in _execute_callable
    return execute_callable(context=context, **execute_callable_kwargs)
           ^^^^^^^^^^^^^^^^^^^^^^^^^^^^^^^^^^^^^^^^^^^^^^^^^^^^^^^^^^^^
  File "/home/airflow/.local/lib/python3.12/site-packages/airflow/models/baseoperator.py", line 400, in wrapper
    return func(self, *args, **kwargs)
           ^^^^^^^^^^^^^^^^^^^^^^^^^^^
  File "/home/airflow/.local/lib/python3.12/site-packages/airflow/operators/python.py", line 235, in execute
    return_value = self.execute_callable()
                   ^^^^^^^^^^^^^^^^^^^^^^^
  File "/home/airflow/.local/lib/python3.12/site-packages/airflow/operators/python.py", line 252, in execute_callable
    return self.python_callable(*self.op_args, **self.op_kwargs)
           ^^^^^^^^^^^^^^^^^^^^^^^^^^^^^^^^^^^^^^^^^^^^^^^^^^^^^
  File "/opt/airflow/dags/main.py", line 42, in load
    subprocess.run(['dvc', 'add', '/tmp/transformed_articles.csv'], check=True)
  File "/usr/local/lib/python3.12/subprocess.py", line 548, in run
    with Popen(*popenargs, **kwargs) as process:
         ^^^^^^^^^^^^^^^^^^^^^^^^^^^
  File "/usr/local/lib/python3.12/subprocess.py", line 1026, in __init__
    self._execute_child(args, executable, preexec_fn, close_fds,
  File "/usr/local/lib/python3.12/subprocess.py", line 1955, in _execute_child
    raise child_exception_type(errno_num, err_msg, err_filename)
PermissionError: [Errno 13] Permission denied: 'dvc'
[2024-05-12T15:36:28.998+0000] {taskinstance.py:1206} INFO - Marking task as UP_FOR_RETRY. dag_id=simple_mlops_dag, task_id=load, run_id=manual__2024-05-12T15:35:55.995449+00:00, execution_date=20240512T153555, start_date=20240512T153628, end_date=20240512T153628
[2024-05-12T15:36:29.048+0000] {standard_task_runner.py:110} ERROR - Failed to execute job 23 for task load ([Errno 13] Permission denied: 'dvc'; 78)
[2024-05-12T15:36:29.068+0000] {local_task_job_runner.py:240} INFO - Task exited with return code 1
[2024-05-12T15:36:29.095+0000] {taskinstance.py:3498} INFO - 0 downstream tasks scheduled from follow-on schedule check
[2024-05-12T15:36:29.098+0000] {local_task_job_runner.py:222} INFO - ::endgroup::
